Workbook

Sheet genus.filtered
A1: # These are results for correlating ASVs and metabolites across all samples, all times | N1: label | O1: ='[1]rclr.padj_cutoff'!B5 -> all
N2: ='[1]rclr.padj_cutoff'!L6 -> sig_q01 | O2: =padj_cutoff!B2 -> 5.6493385e-16
N3: ='[1]rclr.padj_cutoff'!L7 -> sig_q025 | O3: =padj_cutoff!C2 -> 1.7682804e-12
N4: ='[1]rclr.padj_cutoff'!L8 -> sig_q05 | O4: =padj_cutoff!D2 -> 2.0329244e-09
N5: ='[1]rclr.padj_cutoff'!L9 -> maybe | O5: =padj_cutoff!E2 -> 2.0137686e-07
A9: asv_id | B9: simpleName | C9: p_value | D9: estimate | E9: padj_bh | F9: grouping | G9: padj_bh_05 | H9: padj_01 | I9: padj_025 | J9: padj_05 | K9: padj_10 | L9: sig | M9: filtered_estimate
A10: pASV_00003 | B10: cysteate | C10: 3.331208e-10 | D10: 0.66170355 | E10: 9.9943959e-09 | F10: all | G10: 9.9943959e-09 | H10: NA | I10: NA | J10: 3.331208e-10 | K10: 3.331208e-10 | L10: sig_q05 | M10: 0.66170355
A11: pASV_00003 | B11: cysteine 2 | C11: 4.2963416e-11 | D11: 0.68537894 | E11: 1.5846279e-09 | F11: all | G11: 1.5846279e-09 | H11: NA | I11: NA | J11: 4.2963416e-11 | K11: 4.2963416e-11 | L11: sig_q05 | M11: 0.68537894
A12: pASV_00003 | B12: pantothenic acid | C12: 1.6110415e-17 | D12: 0.80814889 | E12: 2.0447592e-15 | F12: all | G12: 2.0447592e-15 | H12: 1.6110415e-17 | I12: 1.6110415e-17 | J12: 1.6110415e-17 | K12: 1.6110415e-17 | L12: sig_q01 | M12: 0.80814889
A13: pASV_00003 | B13: taurine | C13: 3.9696001e-11 | D13: 0.68625084 | E13: 1.4703989e-09 | F13: all | G13: 1.4703989e-09 | H13: NA | I13: NA | J13: 3.9696001e-11 | K13: 3.9696001e-11 | L13: sig_q05 | M13: 0.68625084
A14: pASV_00003 | B14: uridine | C14: 3.6515195e-09 | D14: 0.63105298 | E14: 8.7299302e-08 | F14: all | G14: 8.7299302e-08 | H14: NA | I14: NA | J14: NA | K14: 3.6515195e-09 | L14: maybe | M14: 0.63105298
A15: pASV_00004 | B15: cysteine 2 | C15: 6.2221234e-08 | D15: 0.5898055 | E15: 1.0529622e-06 | F15: all | G15: 1.0529622e-06 | H15: NA | I15: NA | J15: NA | K15: 6.2221234e-08 | L15: maybe | M15: 0.5898055
A16: pASV_00004 | B16: pantothenic acid | C16: 6.8543899e-13 | D16: 0.72726358 | E16: 3.808452e-11 | F16: all | G16: 3.808452e-11 | H16: NA | I16: 6.8543899e-13 | J16: 6.8543899e-13 | K16: 6.8543899e-13 | L16: sig_q025 | M16: 0.72726358
A17: pASV_00004 | B17: taurine | C17: 3.2833902e-08 | D17: 0.59963112 | E17: 6.1160819e-07 | F17: all | G17: 6.1160819e-07 | H17: NA | I17: NA | J17: NA | K17: 3.2833902e-08 | L17: maybe | M17: 0.59963112
A18: pASV_00006 | B18: cysteate | C18: 4.9068714e-10 | D18: 0.65697518 | E18: 1.4291194e-08 | F18: all | G18: 1.4291194e-08 | H18: NA | I18: NA | J18: 4.9068714e-10 | K18: 4.9068714e-10 | L18: sig_q05 | M18: 0.65697518
A19: pASV_00006 | B19: cysteine 2 | C19: 2.2571184e-11 | D19: 0.69238766 | E19: 8.8279922e-10 | F19: all | G19: 8.8279922e-10 | H19: NA | I19: NA | J19: 2.2571184e-11 | K19: 2.2571184e-11 | L19: sig_q05 | M19: 0.69238766
A20: pASV_00006 | B20: pantothenic acid | C20: 8.1482438e-18 | D20: 0.81230718 | E20: 1.0392824e-15 | F20: all | G20: 1.0392824e-15 | H20: 8.1482438e-18 | I20: 8.1482438e-18 | J20: 8.1482438e-18 | K20: 8.1482438e-18 | L20: sig_q01 | M20: 0.81230718
A21: pASV_00006 | B21: taurine | C21: 2.0548499e-11 | D21: 0.6933937 | E21: 8.1726841e-10 | F21: all | G21: 8.1726841e-10 | H21: NA | I21: NA | J21: 2.0548499e-11 | K21: 2.0548499e-11 | L21: sig_q05 | M21: 0.6933937
A22: pASV_00006 | B22: uridine | C22: 3.6424883e-09 | D22: 0.63108652 | E22: 8.716387e-08 | F22: all | G22: 8.716387e-08 | H22: NA | I22: NA | J22: NA | K22: 3.6424883e-09 | L22: maybe | M22: 0.63108652
A23: pASV_00007 | B23: 5'UMP | C23: 9.3129508e-08 | D23: -0.58343394 | E23: 1.4779069e-06 | F23: all | G23: 1.4779069e-06 | H23: NA | I23: NA | J23: NA | K23: 9.3129508e-08 | L23: maybe | M23: -0.58343394
A24: pASV_00007 | B24: cysteate | C24: 7.0179804e-15 | D24: -0.76609658 | E24: 7.0158127e-13 | F24: all | G24: 7.0158127e-13 | H24: NA | I24: 7.0179804e-15 | J24: 7.0179804e-15 | K24: 7.0179804e-15 | L24: sig_q025 | M24: -0.76609658
A25: pASV_00007 | B25: cysteine 2 | C25: 3.0762952e-13 | D25: -0.73457411 | E25: 1.9193117e-11 | F25: all | G25: 1.9193117e-11 | H25: NA | I25: 3.0762952e-13 | J25: 3.0762952e-13 | K25: 3.0762952e-13 | L25: sig_q025 | M25: -0.73457411
A26: pASV_00007 | B26: pantothenic acid | C26: 9.1600054e-21 | D26: -0.84869215 | E26: 1.4731109e-18 | F26: all | G26: 1.4731109e-18 | H26: 9.1600054e-21 | I26: 9.1600054e-21 | J26: 9.1600054e-21 | K26: 9.1600054e-21 | L26: sig_q01 | M26: -0.84869215
A27: pASV_00007 | B27: sn-glycerol 3-phosphate | C27: 9.3152445e-09 | D27: -0.61807512 | E27: 2.0405272e-07 | F27: all | G27: 2.0405272e-07 | H27: NA | I27: NA | J27: NA | K27: 9.3152445e-09 | L27: maybe | M27: -0.61807512
A28: pASV_00007 | B28: taurine | C28: 1.149283e-11 | D28: -0.69953052 | E28: 4.8464551e-10 | F28: all | G28: 4.8464551e-10 | H28: NA | I28: NA | J28: 1.149283e-11 | K28: 1.149283e-11 | L28: sig_q05 | M28: -0.69953052
A29: pASV_00007 | B29: uridine | C29: 7.2654581e-11 | D29: -0.6795104 | E29: 2.5250636e-09 | F29: all | G29: 2.5250636e-09 | H29: NA | I29: NA | J29: 7.2654581e-11 | K29: 7.2654581e-11 | L29: sig_q05 | M29: -0.6795104
A30: pASV_00008 | B30: cysteate | C30: 2.1344212e-08 | D30: -0.60606975 | E30: 4.2543828e-07 | F30: all | G30: 4.2543828e-07 | H30: NA | I30: NA | J30: NA | K30: 2.1344212e-08 | L30: maybe | M30: -0.60606975
A31: pASV_00008 | B31: pantothenic acid | C31: 1.7128577e-07 | D31: -0.57354125 | E31: 2.4693381e-06 | F31: all | G31: 2.4693381e-06 | H31: NA | I31: NA | J31: NA | K31: 1.7128577e-07 | L31: maybe | M31: -0.57354125
A32: pASV_00009 | B32: cysteate | C32: 3.845762e-10 | D32: 0.65995976 | E32: 1.1366949e-08 | F32: all | G32: 1.1366949e-08 | H32: NA | I32: NA | J32: 3.845762e-10 | K32: 3.845762e-10 | L32: sig_q05 | M32: 0.65995976
A33: pASV_00009 | B33: cysteine 2 | C33: 2.7456495e-11 | D33: 0.69027498 | E33: 1.0500791e-09 | F33: all | G33: 1.0500791e-09 | H33: NA | I33: NA | J33: 2.7456495e-11 | K33: 2.7456495e-11 | L33: sig_q05 | M33: 0.69027498
A34: pASV_00009 | B34: pantothenic acid | C34: 7.1671469e-18 | D34: 0.81307847 | E34: 9.1867211e-16 | F34: all | G34: 9.1867211e-16 | H34: 7.1671469e-18 | I34: 7.1671469e-18 | J34: 7.1671469e-18 | K34: 7.1671469e-18 | L34: sig_q01 | M34: 0.81307847
A35: pASV_00009 | B35: taurine | C35: 2.9938668e-11 | D35: 0.68933602 | E35: 1.1366158e-09 | F35: all | G35: 1.1366158e-09 | H35: NA | I35: NA | J35: 2.9938668e-11 | K35: 2.9938668e-11 | L35: sig_q05 | M35: 0.68933602
A36: pASV_00009 | B36: uridine | C36: 3.2573801e-09 | D36: 0.63259557 | E36: 7.882251e-08 | F36: all | G36: 7.882251e-08 | H36: NA | I36: NA | J36: NA | K36: 3.2573801e-09 | L36: maybe | M36: 0.63259557
A37: pASV_00013 | B37: cysteate | C37: 7.8668059e-08 | D37: -0.5861167 | E37: 1.2826659e-06 | F37: all | G37: 1.2826659e-06 | H37: NA | I37: NA | J37: NA | K37: 7.8668059e-08 | L37: maybe | M37: -0.5861167
A38: pASV_00015 | B38: cysteate | C38: 1.1729177e-08 | D38: -0.61478873 | E38: 2.5036426e-07 | F38: all | G38: 2.5036426e-07 | H38: NA | I38: NA | J38: NA | K38: 1.1729177e-08 | L38: maybe | M38: -0.61478873
A39: pASV_00018 | B39: cysteate | C39: 1.2862211e-09 | D39: -0.64483568 | E39: 3.4654356e-08 | F39: all | G39: 3.4654356e-08 | H39: NA | I39: NA | J39: 1.2862211e-09 | K39: 1.2862211e-09 | L39: sig_q05 | M39: -0.64483568
A40: pASV_00018 | B40: cysteine 2 | C40: 3.6998845e-08 | D40: -0.59782025 | E40: 6.7558116e-07 | F40: all | G40: 6.7558116e-07 | H40: NA | I40: NA | J40: NA | K40: 3.6998845e-08 | L40: maybe | M40: -0.59782025
A41: pASV_00018 | B41: pantothenic acid | C41: 4.86695e-10 | D41: -0.65707579 | E41: 1.4206885e-08 | F41: all | G41: 1.4206885e-08 | H41: NA | I41: NA | J41: 4.86695e-10 | K41: 4.86695e-10 | L41: sig_q05 | M41: -0.65707579
A42: pASV_00019 | B42: pantothenic acid | C42: 5.9854935e-09 | D42: 0.62427901 | E42: 1.3726873e-07 | F42: all | G42: 1.3726873e-07 | H42: NA | I42: NA | J42: NA | K42: 5.9854935e-09 | L42: maybe | M42: 0.62427901
A43: pASV_00031 | B43: cysteate | C43: 1.1233202e-12 | D43: -0.72263581 | E43: 5.8286588e-11 | F43: all | G43: 5.8286588e-11 | H43: NA | I43: 1.1233202e-12 | J43: 1.1233202e-12 | K43: 1.1233202e-12 | L43: sig_q025 | M43: -0.72263581
...

Sheet genus.site.filtered
A1: # These are results for correlating ASVs and metabolites across all times, site-specific. | Q1: ='[1]rclr.padj_cutoff'!C5 -> LB_seagrass | R1: ='[1]rclr.padj_cutoff'!D5 -> Tektite | S1: ='[1]rclr.padj_cutoff'!E5 -> Yawzi
P2: ='[1]rclr.padj_cutoff'!L6 -> sig_q01 | Q2: =padj_cutoff!B3 -> 0 | R2: =padj_cutoff!B4 -> 0.00096589396 | S2: =padj_cutoff!B5 -> 0.00020070451
P3: ='[1]rclr.padj_cutoff'!L7 -> sig_q025 | Q3: =padj_cutoff!C3 -> 2.9407095e-05 | R3: =padj_cutoff!C4 -> 0.0038469109 | S3: =padj_cutoff!C5 -> 0.0007932035
P4: ='[1]rclr.padj_cutoff'!L8 -> sig_q05 | Q4: =padj_cutoff!D3 -> 0.00030106828 | R4: =padj_cutoff!E4 -> 0.02252824 | S4: =padj_cutoff!E5 -> 0.0098397506
P5: ='[1]rclr.padj_cutoff'!L9 -> maybe | Q5: =padj_cutoff!E3 -> 0.0022248796 | R5: =padj_cutoff!E4 -> 0.02252824 | S5: =padj_cutoff!E5 -> 0.0098397506
A9: grouping | B9: asv_id | C9: simpleName | D9: p_value | E9: estimate | F9: padj_bh | G9: padj_bh_05 | H9: padj_01 | I9: padj_025 | J9: padj_05 | K9: padj_10 | L9: sig | M9: site | N9: sampling_time | O9: filtered_estimate
A10: LB_seagrass | B10: pASV_00001 | C10: ciliatine | D10: 0.00099793322 | E10: -0.64031621 | F10: 0.048566955 | G10: 0.048566955 | H10: NA | I10: NA | J10: NA | K10: 0.00099793322 | L10: maybe | M10: LB_seagrass | N10: NA | O10: -0.64031621
A11: LB_seagrass | B11: pASV_00028 | C11: homoserine betaine | D11: 0.00038046768 | E11: -0.79642857 | F11: 0.0295637 | G11: 0.0295637 | H11: NA | I11: NA | J11: NA | K11: 0.00038046768 | L11: maybe | M11: LB_seagrass | N11: NA | O11: -0.79642857
A12: LB_seagrass | B12: pASV_00028 | C12: sn-glycerol 3-phosphate | D12: 0.0020110969 | E12: 0.60968379 | F12: 0.071841225 | G12: NA | H12: NA | I12: NA | J12: NA | K12: 0.0020110969 | L12: maybe | M12: LB_seagrass | N12: NA | O12: 0.60968379
A13: LB_seagrass | B13: pASV_00038 | C13: kynurenine | D13: 0.0010049095 | E13: 0.65217391 | F13: 0.048677725 | G13: 0.048677725 | H13: NA | I13: NA | J13: NA | K13: 0.0010049095 | L13: maybe | M13: LB_seagrass | N13: NA | O13: 0.65217391
A14: LB_seagrass | B14: pASV_00038 | C14: pantothenic acid | D14: 0.00013663385 | E14: 0.71245059 | F14: 0.017547729 | G14: 0.017547729 | H14: NA | I14: NA | J14: 0.00013663385 | K14: 0.00013663385 | L14: sig_q05 | M14: LB_seagrass | N14: NA | O14: 0.71245059
A15: LB_seagrass | B15: pASV_00045 | C15: pantothenic acid | D15: 9.307933e-05 | E15: 0.7243083 | F15: 0.014202576 | G15: 0.014202576 | H15: NA | I15: NA | J15: 9.307933e-05 | K15: 9.307933e-05 | L15: sig_q05 | M15: LB_seagrass | N15: NA | O15: 0.7243083
A16: LB_seagrass | B16: pASV_00058 | C16: kynurenine | D16: 0.0021621583 | E16: 0.61829475 | F16: 0.073951825 | G16: NA | H16: NA | I16: NA | J16: NA | K16: 0.0021621583 | L16: maybe | M16: LB_seagrass | N16: NA | O16: 0.61829475
A17: LB_seagrass | B17: pASV_00058 | C17: pantothenic acid | D17: 6.6474103e-08 | E17: 0.87055336 | F17: 2.1959069e-05 | G17: 2.1959069e-05 | H17: NA | I17: 6.6474103e-08 | J17: 6.6474103e-08 | K17: 6.6474103e-08 | L17: sig_q025 | M17: LB_seagrass | N17: NA | O17: 0.87055336
A18: LB_seagrass | B18: pASV_00060 | C18: ciliatine | D18: 0.00070925869 | E18: 0.6541502 | F18: 0.041321411 | G18: 0.041321411 | H18: NA | I18: NA | J18: NA | K18: 0.00070925869 | L18: maybe | M18: LB_seagrass | N18: NA | O18: 0.6541502
A19: LB_seagrass | B19: pASV_00060 | C19: kynurenine | D19: 0.00018196803 | E19: 0.71541502 | F19: 0.020316382 | G19: 0.020316382 | H19: NA | I19: NA | J19: 0.00018196803 | K19: 0.00018196803 | L19: sig_q05 | M19: LB_seagrass | N19: NA | O19: 0.71541502
A20: LB_seagrass | B20: pASV_00060 | C20: pantothenic acid | D20: 1.414903e-06 | E20: 0.82312253 | F20: 0.00040121892 | G20: 0.00040121892 | H20: NA | I20: 1.414903e-06 | J20: 1.414903e-06 | K20: 1.414903e-06 | L20: sig_q025 | M20: LB_seagrass | N20: NA | O20: 0.82312253
A21: LB_seagrass | B21: pASV_00092 | C21: homoserine betaine | D21: 0.00082932963 | E21: -0.76785714 | F21: 0.044775416 | G21: 0.044775416 | H21: NA | I21: NA | J21: NA | K21: 0.00082932963 | L21: maybe | M21: LB_seagrass | N21: NA | O21: -0.76785714
A22: LB_seagrass | B22: pASV_00094 | C22: pantothenic acid | D22: 0.00042246285 | E22: 0.67391304 | F22: 0.031628451 | G22: 0.031628451 | H22: NA | I22: NA | J22: NA | K22: 0.00042246285 | L22: maybe | M22: LB_seagrass | N22: NA | O22: 0.67391304
A23: LB_seagrass | B23: pASV_00097 | C23: kynurenine | D23: 0.00053896391 | E23: 0.67701863 | F23: 0.035535022 | G23: 0.035535022 | H23: NA | I23: NA | J23: NA | K23: 0.00053896391 | L23: maybe | M23: LB_seagrass | N23: NA | O23: 0.67701863
A24: LB_seagrass | B24: pASV_00097 | C24: pantothenic acid | D24: 3.9181621e-05 | E24: 0.74901186 | F24: 0.0076788788 | G24: 0.0076788788 | H24: NA | I24: NA | J24: 3.9181621e-05 | K24: 3.9181621e-05 | L24: sig_q05 | M24: LB_seagrass | N24: NA | O24: 0.74901186
A25: LB_seagrass | B25: pASV_00105 | C25: kynurenine | D25: 0.00047824465 | E25: 0.68153586 | F25: 0.032831237 | G25: 0.032831237 | H25: NA | I25: NA | J25: NA | K25: 0.00047824465 | L25: maybe | M25: LB_seagrass | N25: NA | O25: 0.68153586
A26: LB_seagrass | B26: pASV_00105 | C26: pantothenic acid | D26: 4.5290212e-05 | E26: 0.74505929 | F26: 0.0085618541 | G26: 0.0085618541 | H26: NA | I26: NA | J26: 4.5290212e-05 | K26: 4.5290212e-05 | L26: sig_q05 | M26: LB_seagrass | N26: NA | O26: 0.74505929
A27: LB_seagrass | B27: pASV_00111 | C27: ciliatine | D27: 0.00090669909 | E27: 0.64426877 | F27: 0.046368322 | G27: 0.046368322 | H27: NA | I27: NA | J27: NA | K27: 0.00090669909 | L27: maybe | M27: LB_seagrass | N27: NA | O27: 0.64426877
A28: LB_seagrass | B28: pASV_00111 | C28: kynurenine | D28: 0.00037421882 | E28: 0.6905703 | F28: 0.0295637 | G28: 0.0295637 | H28: NA | I28: NA | J28: NA | K28: 0.00037421882 | L28: maybe | M28: LB_seagrass | N28: NA | O28: 0.6905703
A29: LB_seagrass | B29: pASV_00111 | C29: pantothenic acid | D29: 6.550563e-06 | E29: 0.79249012 | F29: 0.0016462721 | G29: 0.0016462721 | H29: NA | I29: 6.550563e-06 | J29: 6.550563e-06 | K29: 6.550563e-06 | L29: sig_q025 | M29: LB_seagrass | N29: NA | O29: 0.79249012
A30: LB_seagrass | B30: pASV_00124 | C30: kynurenine | D30: 0.0012113881 | E30: 0.64426877 | F30: 0.053911819 | G30: NA | H30: NA | I30: NA | J30: NA | K30: 0.0012113881 | L30: maybe | M30: LB_seagrass | N30: NA | O30: 0.64426877
A31: LB_seagrass | B31: pASV_00131 | C31: ciliatine | D31: 0.0012903808 | E31: 0.62944664 | F31: 0.056370379 | G31: NA | H31: NA | I31: NA | J31: NA | K31: 0.0012903808 | L31: maybe | M31: LB_seagrass | N31: NA | O31: 0.62944664
A32: LB_seagrass | B32: pASV_00131 | C32: kynurenine | D32: 0.00060617789 | E32: 0.67250141 | F32: 0.038034668 | G32: 0.038034668 | H32: NA | I32: NA | J32: NA | K32: 0.00060617789 | L32: maybe | M32: LB_seagrass | N32: NA | O32: 0.67250141
A33: LB_seagrass | B33: pASV_00131 | C33: pantothenic acid | D33: 3.0213401e-08 | E33: 0.88043478 | F33: 1.0244741e-05 | G33: 1.0244741e-05 | H33: NA | I33: 3.0213401e-08 | J33: 3.0213401e-08 | K33: 3.0213401e-08 | L33: sig_q025 | M33: LB_seagrass | N33: NA | O33: 0.88043478
A34: LB_seagrass | B34: pASV_00147 | C34: pantothenic acid | D34: 1.667852e-08 | E34: 0.88735178 | F34: 5.7465573e-06 | G34: 5.7465573e-06 | H34: NA | I34: 1.667852e-08 | J34: 1.667852e-08 | K34: 1.667852e-08 | L34: sig_q025 | M34: LB_seagrass | N34: NA | O34: 0.88735178
A35: LB_seagrass | B35: pASV_00164 | C35: kynurenine | D35: 0.0016494006 | E35: 0.63071711 | F35: 0.064218402 | G35: NA | H35: NA | I35: NA | J35: NA | K35: 0.0016494006 | L35: maybe | M35: LB_seagrass | N35: NA | O35: 0.63071711
A36: LB_seagrass | B36: pASV_00164 | C36: pantothenic acid | D36: 0.00042246285 | E36: 0.67391304 | F36: 0.031628451 | G36: 0.031628451 | H36: NA | I36: NA | J36: NA | K36: 0.00042246285 | L36: maybe | M36: LB_seagrass | N36: NA | O36: 0.67391304
A37: LB_seagrass | B37: pASV_00168 | C37: sn-glycerol 3-phosphate | D37: 9.307933e-05 | E37: -0.7243083 | F37: 0.014202576 | G37: 0.014202576 | H37: NA | I37: NA | J37: 9.307933e-05 | K37: 9.307933e-05 | L37: sig_q05 | M37: LB_seagrass | N37: NA | O37: -0.7243083
A38: LB_seagrass | B38: pASV_00215 | C38: ciliatine | D38: 0.00092880937 | E38: 0.64328063 | F38: 0.047017123 | G38: 0.047017123 | H38: NA | I38: NA | J38: NA | K38: 0.00092880937 | L38: maybe | M38: LB_seagrass | N38: NA | O38: 0.64328063
A39: LB_seagrass | B39: pASV_00215 | C39: kynurenine | D39: 0.00078411879 | E39: 0.66233766 | F39: 0.043849072 | G39: 0.043849072 | H39: NA | I39: NA | J39: NA | K39: 0.00078411879 | L39: maybe | M39: LB_seagrass | N39: NA | O39: 0.66233766
A40: LB_seagrass | B40: pASV_00215 | C40: pantothenic acid | D40: 1.0352344e-07 | E40: 0.86462451 | F40: 3.3677174e-05 | G40: 3.3677174e-05 | H40: NA | I40: 1.0352344e-07 | J40: 1.0352344e-07 | K40: 1.0352344e-07 | L40: sig_q025 | M40: LB_seagrass | N40: NA | O40: 0.86462451
A41: LB_seagrass | B41: pASV_00217 | C41: ciliatine | D41: 0.0017658182 | E41: -0.61561265 | F41: 0.066802967 | G41: NA | H41: NA | I41: NA | J41: NA | K41: 0.0017658182 | L41: maybe | M41: LB_seagrass | N41: NA | O41: -0.61561265
A42: LB_seagrass | B42: pASV_00217 | C42: sn-glycerol 3-phosphate | D42: 9.9360547e-05 | E42: -0.72233202 | F42: 0.01477406 | G42: 0.01477406 | H42: NA | I42: NA | J42: 9.9360547e-05 | K42: 9.9360547e-05 | L42: sig_q05 | M42: LB_seagrass | N42: NA | O42: -0.72233202
A43: LB_seagrass | B43: pASV_00219 | C43: homoserine betaine | D43: 0.00027524427 | E43: 0.80714286 | F43: 0.02505583 | G43: 0.02505583 | H43: NA | I43: NA | J43: 0.00027524427 | K43: 0.00027524427 | L43: sig_q05 | M43: LB_seagrass | N43: NA | O43: 0.80714286
...

Sheet genus.site.time.filtered
A1: # These are results for correlating ASVs and metabolites in site- and time-specific groups.
P2: ='[1]rclr.padj_cutoff'!F5 -> LB_seagrass.dawn | Q2: ='[1]rclr.padj_cutoff'!G5 -> LB_seagrass.peak_photo | R2: ='[1]rclr.padj_cutoff'!H5 -> Tektite.dawn | S2: ='[1]rclr.padj_cutoff'!I5 -> Tektite.peak_photo | T2: ='[1]rclr.padj_cutoff'!J5 -> Yawzi.dawn | U2: ='[1]rclr.padj_cutoff'!K5 -> Yawzi.peak_photo
O3: ='[1]rclr.padj_cutoff'!L6 -> sig_q01 | P3: =padj_cutoff!B6 -> 0.000246448 | Q3: =padj_cutoff!B7 -> 0 | R3: =padj_cutoff!B8 -> 0 | S3: =padj_cutoff!B9 -> 0.0034288789 | T3: =padj_cutoff!B10 -> 0 | U3: =padj_cutoff!B11 -> 4.5090966e-05
O4: ='[1]rclr.padj_cutoff'!L7 -> sig_q025 | P4: =padj_cutoff!C6 -> 0.0021562814 | Q4: =padj_cutoff!C7 -> 0.00088821349 | R4: =padj_cutoff!C8 -> 0.00036306586 | S4: =padj_cutoff!C9 -> 0.010118391 | T4: =padj_cutoff!C10 -> 0.0079321831 | U4: =padj_cutoff!C11 -> 0.00091962593
O5: ='[1]rclr.padj_cutoff'!L8 -> sig_q05 | P5: =padj_cutoff!D6 -> 0.0080557351 | Q5: =padj_cutoff!D7 -> 0.004226414 | R5: =padj_cutoff!D8 -> 0.0014282106 | S5: =padj_cutoff!D9 -> 0.026369558 | T5: =padj_cutoff!D10 -> 0.026902417 | U5: =padj_cutoff!D11 -> 0.0032653336
O6: ='[1]rclr.padj_cutoff'!L9 -> maybe | P6: =padj_cutoff!E6 -> 0.026164521 | Q6: =padj_cutoff!E7 -> 0.013097076 | R6: =padj_cutoff!E8 -> 0.0038175164 | S6: =padj_cutoff!E9 -> 0.06978834 | T6: =padj_cutoff!E10 -> 0.060493174 | U6: =padj_cutoff!E11 -> 0.0089424468
A9: grouping | B9: asv_id | C9: simpleName | D9: p_value | E9: estimate | F9: padj_bh | G9: padj_bh_05 | H9: padj_01 | I9: padj_025 | J9: padj_05 | K9: padj_10 | L9: sig | M9: site | N9: sampling_time | O9: filtered_estimate
A10: LB_seagrass.dawn | B10: pASV_00001 | C10: ciliatine | D10: 0.016831456 | E10: -0.67132867 | F10: 0.25373696 | G10: NA | H10: NA | I10: NA | J10: NA | K10: 0.016831456 | L10: maybe | M10: LB_seagrass | N10: dawn | O10: -0.67132867
A11: LB_seagrass.dawn | B11: pASV_00001 | C11: sn-glycerol 3-phosphate | D11: 0.0092017798 | E11: -0.71328671 | F11: 0.20088471 | G11: NA | H11: NA | I11: NA | J11: NA | K11: 0.0092017798 | L11: maybe | M11: LB_seagrass | N11: dawn | O11: -0.71328671
A12: LB_seagrass.dawn | B12: pASV_00003 | C12: homoserine betaine | D12: 0.0031104283 | E12: 0.8 | F12: 0.13954929 | G12: NA | H12: NA | I12: NA | J12: 0.0031104283 | K12: 0.0031104283 | L12: sig_q05 | M12: LB_seagrass | N12: dawn | O12: 0.8
A13: LB_seagrass.dawn | B13: pASV_00003 | C13: sn-glycerol 3-phosphate | D13: 0.018452718 | E13: -0.66433566 | F13: 0.26141116 | G13: NA | H13: NA | I13: NA | J13: NA | K13: 0.018452718 | L13: maybe | M13: LB_seagrass | N13: dawn | O13: -0.66433566
A14: LB_seagrass.dawn | B14: pASV_00003 | C14: spermidine 3 | D14: 0.025984134 | E14: -0.66363636 | F14: 0.30036179 | G14: NA | H14: NA | I14: NA | J14: NA | K14: 0.025984134 | L14: maybe | M14: LB_seagrass | N14: dawn | O14: -0.66363636
A15: LB_seagrass.dawn | B15: pASV_00004 | C15: ciliatine | D15: 0.0065434901 | E15: -0.73426573 | F15: 0.17862835 | G15: NA | H15: NA | I15: NA | J15: 0.0065434901 | K15: 0.0065434901 | L15: sig_q05 | M15: LB_seagrass | N15: dawn | O15: -0.73426573
A16: LB_seagrass.dawn | B16: pASV_00004 | C16: sn-glycerol 3-phosphate | D16: 0.015317329 | E16: -0.67832168 | F16: 0.24762575 | G16: NA | H16: NA | I16: NA | J16: NA | K16: 0.015317329 | L16: maybe | M16: LB_seagrass | N16: dawn | O16: -0.67832168
A17: LB_seagrass.dawn | B17: pASV_00004 | C17: spermidine 3 | D17: 0.00061169385 | E17: -0.86363636 | F17: 0.052901974 | G17: NA | H17: NA | I17: 0.00061169385 | J17: 0.00061169385 | K17: 0.00061169385 | L17: sig_q025 | M17: LB_seagrass | N17: dawn | O17: -0.86363636
A18: LB_seagrass.dawn | B18: pASV_00006 | C18: homoserine betaine | D18: 0.014552052 | E18: 0.70909091 | F18: 0.24489661 | G18: NA | H18: NA | I18: NA | J18: NA | K18: 0.014552052 | L18: maybe | M18: LB_seagrass | N18: dawn | O18: 0.70909091
A19: LB_seagrass.dawn | B19: pASV_00006 | C19: sn-glycerol 3-phosphate | D19: 0.022034191 | E19: -0.65034965 | F19: 0.27881243 | G19: NA | H19: NA | I19: NA | J19: NA | K19: 0.022034191 | L19: maybe | M19: LB_seagrass | N19: dawn | O19: -0.65034965
A20: LB_seagrass.dawn | B20: pASV_00006 | C20: spermidine 3 | D20: 0.0084547289 | E20: -0.74545455 | F20: 0.19522723 | G20: NA | H20: NA | I20: NA | J20: NA | K20: 0.0084547289 | L20: maybe | M20: LB_seagrass | N20: dawn | O20: -0.74545455
A21: LB_seagrass.dawn | B21: pASV_00009 | C21: homoserine betaine | D21: 0.007282041 | E21: 0.75454545 | F21: 0.1856924 | G21: NA | H21: NA | I21: NA | J21: 0.007282041 | K21: 0.007282041 | L21: sig_q05 | M21: LB_seagrass | N21: dawn | O21: 0.75454545
A22: LB_seagrass.dawn | B22: pASV_00009 | C22: sn-glycerol 3-phosphate | D22: 0.020185499 | E22: -0.65734266 | F22: 0.2742902 | G22: NA | H22: NA | I22: NA | J22: NA | K22: 0.020185499 | L22: maybe | M22: LB_seagrass | N22: dawn | O22: -0.65734266
A23: LB_seagrass.dawn | B23: pASV_00009 | C23: spermidine 3 | D23: 0.020842854 | E23: -0.68181818 | F23: 0.27575568 | G23: NA | H23: NA | I23: NA | J23: NA | K23: 0.020842854 | L23: maybe | M23: LB_seagrass | N23: dawn | O23: -0.68181818
A24: LB_seagrass.dawn | B24: pASV_00014 | C24: ciliatine | D24: 0.0065434901 | E24: -0.73426573 | F24: 0.17862835 | G24: NA | H24: NA | I24: NA | J24: 0.0065434901 | K24: 0.0065434901 | L24: sig_q05 | M24: LB_seagrass | N24: dawn | O24: -0.73426573
A25: LB_seagrass.dawn | B25: pASV_00014 | C25: sn-glycerol 3-phosphate | D25: 0.015317329 | E25: -0.67832168 | F25: 0.24762575 | G25: NA | H25: NA | I25: NA | J25: NA | K25: 0.015317329 | L25: maybe | M25: LB_seagrass | N25: dawn | O25: -0.67832168
A26: LB_seagrass.dawn | B26: pASV_00014 | C26: spermidine 3 | D26: 0.00061169385 | E26: -0.86363636 | F26: 0.052901974 | G26: NA | H26: NA | I26: 0.00061169385 | J26: 0.00061169385 | K26: 0.00061169385 | L26: sig_q025 | M26: LB_seagrass | N26: dawn | O26: -0.86363636
A27: LB_seagrass.dawn | B27: pASV_00019 | C27: ciliatine | D27: 0.0045084355 | E27: -0.75524476 | F27: 0.15940045 | G27: NA | H27: NA | I27: NA | J27: 0.0045084355 | K27: 0.0045084355 | L27: sig_q05 | M27: LB_seagrass | N27: dawn | O27: -0.75524476
A28: LB_seagrass.dawn | B28: pASV_00019 | C28: sn-glycerol 3-phosphate | D28: 0.022034191 | E28: -0.65034965 | F28: 0.27881243 | G28: NA | H28: NA | I28: NA | J28: NA | K28: 0.022034191 | L28: maybe | M28: LB_seagrass | N28: dawn | O28: -0.65034965
A29: LB_seagrass.dawn | B29: pASV_00019 | C29: spermidine 3 | D29: 0.0003301688 | E29: -0.88181818 | F29: 0.031946787 | G29: 0.031946787 | H29: NA | I29: 0.0003301688 | J29: 0.0003301688 | K29: 0.0003301688 | L29: sig_q025 | M29: LB_seagrass | N29: dawn | O29: -0.88181818
A30: LB_seagrass.dawn | B30: pASV_00021 | C30: ciliatine | D30: 0.026096891 | E30: -0.63636364 | F30: 0.30036179 | G30: NA | H30: NA | I30: NA | J30: NA | K30: 0.026096891 | L30: maybe | M30: LB_seagrass | N30: dawn | O30: -0.63636364
A31: LB_seagrass.dawn | B31: pASV_00021 | C31: sn-glycerol 3-phosphate | D31: 0.0073550289 | E31: -0.72727273 | F31: 0.1856924 | G31: NA | H31: NA | I31: NA | J31: 0.0073550289 | K31: 0.0073550289 | L31: sig_q05 | M31: LB_seagrass | N31: dawn | O31: -0.72727273
A32: LB_seagrass.dawn | B32: pASV_00021 | C32: spermidine 3 | D32: 0.0013331851 | E32: -0.83636364 | F32: 0.090894889 | G32: NA | H32: NA | I32: 0.0013331851 | J32: 0.0013331851 | K32: 0.0013331851 | L32: sig_q025 | M32: LB_seagrass | N32: dawn | O32: -0.83636364
A33: LB_seagrass.dawn | B33: pASV_00028 | C33: homoserine betaine | D33: 0.0003301688 | E33: -0.88181818 | F33: 0.031946787 | G33: 0.031946787 | H33: NA | I33: 0.0003301688 | J33: 0.0003301688 | K33: 0.0003301688 | L33: sig_q025 | M33: LB_seagrass | N33: dawn | O33: -0.88181818
A34: LB_seagrass.dawn | B34: pASV_00028 | C34: tryptophan | D34: 0.018452718 | E34: -0.66433566 | F34: 0.26141116 | G34: NA | H34: NA | I34: NA | J34: NA | K34: 0.018452718 | L34: maybe | M34: LB_seagrass | N34: dawn | O34: -0.66433566
A35: LB_seagrass.dawn | B35: pASV_00036 | C35: ciliatine | D35: 0.0092017798 | E35: -0.71328671 | F35: 0.20088471 | G35: NA | H35: NA | I35: NA | J35: NA | K35: 0.0092017798 | L35: maybe | M35: LB_seagrass | N35: dawn | O35: -0.71328671
A36: LB_seagrass.dawn | B36: pASV_00036 | C36: sn-glycerol 3-phosphate | D36: 0.0045084355 | E36: -0.75524476 | F36: 0.15940045 | G36: NA | H36: NA | I36: NA | J36: 0.0045084355 | K36: 0.0045084355 | L36: sig_q05 | M36: LB_seagrass | N36: dawn | O36: -0.75524476
A37: LB_seagrass.dawn | B37: pASV_00036 | C37: spermidine 3 | D37: 0.00061169385 | E37: -0.86363636 | F37: 0.052901974 | G37: NA | H37: NA | I37: 0.00061169385 | J37: 0.00061169385 | K37: 0.00061169385 | L37: sig_q025 | M37: LB_seagrass | N37: dawn | O37: -0.86363636
A38: LB_seagrass.dawn | B38: pASV_00038 | C38: homoserine betaine | D38: 0.0052994872 | E38: 0.77272727 | F38: 0.16855382 | G38: NA | H38: NA | I38: NA | J38: 0.0052994872 | K38: 0.0052994872 | L38: sig_q05 | M38: LB_seagrass | N38: dawn | O38: 0.77272727
A39: LB_seagrass.dawn | B39: pASV_00038 | C39: putrescine 2 | D39: 0.00086296818 | E39: -0.92857143 | F39: 0.070578759 | G39: NA | H39: NA | I39: 0.00086296818 | J39: 0.00086296818 | K39: 0.00086296818 | L39: sig_q025 | M39: LB_seagrass | N39: dawn | O39: -0.92857143
A40: LB_seagrass.dawn | B40: pASV_00045 | C40: homoserine betaine | D40: 0.014552052 | E40: 0.70909091 | F40: 0.24489661 | G40: NA | H40: NA | I40: NA | J40: NA | K40: 0.014552052 | L40: maybe | M40: LB_seagrass | N40: dawn | O40: 0.70909091
A41: LB_seagrass.dawn | B41: pASV_00045 | C41: putrescine 2 | D41: 0.0065300173 | E41: -0.85714286 | F41: 0.17862835 | G41: NA | H41: NA | I41: NA | J41: 0.0065300173 | K41: 0.0065300173 | L41: sig_q05 | M41: LB_seagrass | N41: dawn | O41: -0.85714286
A42: LB_seagrass.dawn | B42: pASV_00058 | C42: pantothenic acid | D42: 0.0082397687 | E42: 0.72027972 | F42: 0.19522723 | G42: NA | H42: NA | I42: NA | J42: NA | K42: 0.0082397687 | L42: maybe | M42: LB_seagrass | N42: dawn | O42: 0.72027972
...

Sheet padj_cutoff
A1: model | B1: q_01 | C1: q_025 | D1: q_05 | E1: q_10
A2: all | B2: 5.6493385e-16 | C2: 1.7682804e-12 | D2: 2.0329244e-09 | E2: 2.0137686e-07
A3: LB_seagrass | B3: 0 | C3: 2.9407095e-05 | D3: 0.00030106828 | E3: 0.0022248796
A4: Tektite | B4: 0.00096589396 | C4: 0.0038469109 | D4: 0.010428926 | E4: 0.02252824
A5: Yawzi | B5: 0.00020070451 | C5: 0.0007932035 | D5: 0.0027013187 | E5: 0.0098397506
A6: LB_seagrass.dawn | B6: 0.000246448 | C6: 0.0021562814 | D6: 0.0080557351 | E6: 0.026164521
A7: LB_seagrass.peak_photo | B7: 0 | C7: 0.00088821349 | D7: 0.004226414 | E7: 0.013097076
A8: Tektite.dawn | B8: 0 | C8: 0.00036306586 | D8: 0.0014282106 | E8: 0.0038175164
A9: Tektite.peak_photo | B9: 0.0034288789 | C9: 0.010118391 | D9: 0.026369558 | E9: 0.06978834
A10: Yawzi.dawn | B10: 0 | C10: 0.0079321831 | D10: 0.026902417 | E10: 0.060493174
A11: Yawzi.peak_photo | B11: 4.5090966e-05 | C11: 0.00091962593 | D11: 0.0032653336 | E11: 0.0089424468
